Workbook

Sheet Hoja1
A1: NUMERO RP4 | B1: RUTA | C1: SUPERVISOR | D1: NUMERO DE SERIE | E1: IS EN REPARACIÓN | F1: RETORNÓ D REPARACIÓN | G1: CAMBIO DE BATERIA
A2: RP4-A00N0B02 | B2: DS0005 | C2: ALEXANDER SAÑA | D2: S/N 21077N0177
A3: RP4-A00N0B02 | B3: DS0006 | C3: ALEXANDER SAÑA | D3: S/N 21076N09C3 | E3: 45988 | F3: 46027 | G3: SI
A4: RP4-A00N0B02 | B4: DS0007 | C4: ALEXANDER SAÑA | D4: S/N 21179N0149
A5: RP4-A00N0B02 | B5: DS0009 | C5: ALEXANDER SAÑA | D5: S/N 21167N0372
A6: RP4-A00N0B02 | B6: DS0011 | C6: ALEXANDER SAÑA | D6: S/N 21069N089C | E6: 45919 | F6: 7/10/2025/30/04/26
A7: RP4-A00N0B02 | B7: DS0022 | C7: ALEXANDER SAÑA | D7: S/N 21167N0368
A8: RP4-A00N0B02 | B8: DS0036 | C8: ALEXANDER SAÑA | D8: S/N 21077N0178
A9: RP4-A00N0B02 | B9: DS0037 | C9: ALEXANDER SAÑA | D9: S/N 21076N0B3A | F9: 46206
A10: RP4-A00N0B02 | B10: DS0038 | C10: ALEXANDER SAÑA | D10: S/N 21076N0B4A | E10: 45988 | G10: SI
A11: RP4-A00N0B02 | B11: DS0040 | C11: ALEXANDER SAÑA | D11: S/N 21076N0B62
A12: RP4-A00N0B02 | B12: DS0046 | C12: ALEXANDER SAÑA | D12: S/N 21167N035E | E12: 45980 | F12: 45995
A13: RP4-A00N0B02 | B13: DS0059 | C13: ALEXANDER SAÑA | D13: S/N 21091N0A7E
A14: RP4-A00N0B02 | B14: DS0062 | C14: ALEXANDER SAÑA | D14: S/N 21069N0098
A15: RP4-A00N0B02 | B15: DS0066 | C15: ALEXANDER SAÑA | D15: S/N21069N0896/PR21180N0317
A16: RP4-A00N0B02 | B16: DS0072 | C16: ALEXANDER SAÑA | D16: S/N 21179N0123
A17: RP4-A00N0B02 | B17: DS0080 | C17: ALEXANDER SAÑA | D17: S/N 21168N03EE
A18: RP4-A00N0B02 | B18: DS0084 | C18: ALEXANDER SAÑA | D18: S/N 21078N5592
A19: RP4-A00N0B02 | B19: DS00E2 | C19: ALEXANDER SAÑA | D19: S/N 21069N007D | E19: 45924 | F19: 46027
A20: RP4-A00N0B02 | B20: DS0003 | C20: BRIAN LAZO | D20: S/N 21167N0393
A21: RP4-A00N0B02 | B21: DS0013 | C21: BRIAN LAZO | D21: S/N 21180N0319 | E21: 45709
A22: RP4-A00N0B02 | B22: DS0019 | C22: BRIAN LAZO | D22: S/N 21070N0211 | E22: 45953 | F22: 5/1/2026-09/06/26
A23: RP4-A00N0B02 | B23: DS0023 | C23: BRIAN LAZO | D23: S/N 21078N5067
A24: RP4-A00N0B02 | B24: DS0031 | C24: BRIAN LAZO | D24: S/N 21077N017B
A25: RP4-A00N0B02 | B25: DS0033 | C25: BRIAN LAZO | D25: S/N 21077N0192 | E25: 45901 | F25: 45715 | G25: 22313N03AA
A26: RP4-A00N0B02 | B26: DS0034 | C26: BRIAN LAZO | D26: S/N 21076N0B1F | F26: 46086
A27: RP4-ASVSYIR0085 | B27: DS0035 | C27: BRIAN LAZO | D27: S/N 21090N0962 | E27: 27/6/2025/19/09-02/10 | F27: 3/9/2025-24/09/17-10
A28: RP4-A00N0B02 | B28: DS0050 | C28: BRIAN LAZO | D28: S/N 21078N5414 | E28: 45988 | G28: SI | I28: 45880 | J28: 45889
A29: RP4-A00N0B02 | B29: DS0054 | C29: BRIAN LAZO | D29: S/N 21070N020A
A30: RP4-A00N0B02 | B30: DS0061 | C30: BRIAN LAZO | D30: S/N 21076N0B5C | F30: 46086
A31: RP4-A00N0B02 | B31: DS0076 | C31: BRIAN LAZO | D31: S/N 21076N0B65 | E31: 45980 | F31: 45995
A32: RP4-A00N0B02 | B32: DS0083 | C32: BRIAN LAZO | D32: S/N 21077N017D
A33: RP4-A00N0B02 | B33: DS0086 | C33: BRIAN LAZO | D33: S/N 21180N031F | E33: 45901 | F33: 45912
A34: RP4-A00N0B02 | B34: DS0086BIS/DS0035 | C34: BRIAN LAZO | D34: S/N 21180N031F
A35: RP4-A00N0B02 | B35: DS0088 | C35: BRIAN LAZO | D35: S/N 21088N078C | E35: RECUPERADO | F35: 20/11/2025-09/06/26 | G35: SI
A36: RP4-A00N0B02 | B36: DS00A3 | C36: BRIAN LAZO | D36: S/N 21076N0B4B | E36: 45901 | F36: 12/9/2025--16/05/26
A37: RP4-A00N0B02 | B37: DS00B4 | C37: BRIAN LAZO | D37: S/N 21077N01BF
A38: RP4-A00N0B02 | B38: DS00B8 | C38: BRIAN LAZO | D38: S/N 21076N0B63
A39: RP4-A00N0B02 | B39: DS0008 | C39: COORDINACION | D39: S/N 21180N031C | F39: 45981 | G39: ESTA FÍSICO
A40: RP4-A00N0B02 | B40: DS0015 | C40: COORDINACION | D40: S/N 21168N03E9
...

Sheet Impresoras Julio 2026
A1: NUMERO RP4 | B1: NUEVA RUTA | C1: SUPERVISOR | D1: NUMERO DE SERIE | E1: SERIE | F1: Validacion | G1: Columna1 | H1: STICKER ACTUALIZADO | I1: COMENTARIO
A2: RP4-A00N0B02 | B2: DS00EH | C2: KASSANDRA HERNÁNDEZ | D2: S/N 21069N007D | E2: =RIGHT(Tabla1[[#This Row],[NUMERO DE SERIE ]],10) -> 21069N007D | F2: ok | G2: =_xlfn.XLOOKUP(Tabla1[[#This Row],[SERIE]],'DATA IT'!D:D,'DATA IT'!G:G) -> RP4B
A3: RP4-A00N0B02 | B3: Pendiente de Asignar | C3: Coordinación | D3: S/N 21069N007E | E3: =RIGHT(Tabla1[[#This Row],[NUMERO DE SERIE ]],10) -> 21069N007E | F3: ok | G3: =_xlfn.XLOOKUP(Tabla1[[#This Row],[SERIE]],'DATA IT'!D:D,'DATA IT'!G:G) -> RP4B | H3: NOK
A4: RP4-A00N0B02 | B4: DS00U2 | C4: BRYAN GALDÁMEZ | D4: S/N 21069N007F | E4: =RIGHT(Tabla1[[#This Row],[NUMERO DE SERIE ]],10) -> 21069N007F | F4: ok | G4: =_xlfn.XLOOKUP(Tabla1[[#This Row],[SERIE]],'DATA IT'!D:D,'DATA IT'!G:G) -> RP4B
A5: RP4-A00N0B02 | B5: DUMMY HOD | C5: KASSANDRA HERNÁNDEZ | D5: S/N 21069N0097 | E5: =RIGHT(Tabla1[[#This Row],[NUMERO DE SERIE ]],10) -> 21069N0097 | F5: ok | G5: =_xlfn.XLOOKUP(Tabla1[[#This Row],[SERIE]],'DATA IT'!D:D,'DATA IT'!G:G) -> RP4B | H5: NOK
A6: RP4-A00N0B02 | B6: Pendiente de Asignar | C6: Coordinación | D6: S/N 21069N009B | E6: 21069N0098 | F6: ok | G6: =_xlfn.XLOOKUP(Tabla1[[#This Row],[SERIE]],'DATA IT'!D:D,'DATA IT'!G:G) -> RP4B | H6: NOK | I6: No funciona
A7: RP4-A00N0B02 | B7: DUMMY HOD | C7: KASSANDRA HERNÁNDEZ | D7: S/N 21069N0099 | E7: =RIGHT(Tabla1[[#This Row],[NUMERO DE SERIE ]],10) -> 21069N0099 | F7: ok | G7: =_xlfn.XLOOKUP(Tabla1[[#This Row],[SERIE]],'DATA IT'!D:D,'DATA IT'!G:G) -> RP4B | H7: NOK
A8: RP4-A00N0B02 | B8: DUMMY HOD | C8: KASSANDRA HERNÁNDEZ | D8: S/N 21069N009A | E8: =RIGHT(Tabla1[[#This Row],[NUMERO DE SERIE ]],10) -> 21069N009A | F8: ok | G8: =_xlfn.XLOOKUP(Tabla1[[#This Row],[SERIE]],'DATA IT'!D:D,'DATA IT'!G:G) -> RP4B | H8: NOK
A9: RP4-A00N0B02 | B9: Pendiente de Asignar | C9: Coordinación | D9: S/N 21069N0874 | E9: =RIGHT(Tabla1[[#This Row],[NUMERO DE SERIE ]],10) -> 21069N0874 | F9: ok | G9: =_xlfn.XLOOKUP(Tabla1[[#This Row],[SERIE]],'DATA IT'!D:D,'DATA IT'!G:G) -> RP4B | H9: NOK
A10: RP4-A00N0B02 | B10: Pendiente de Asignar | C10: Coordinación | D10: S/N 21069N087E | E10: =RIGHT(Tabla1[[#This Row],[NUMERO DE SERIE ]],10) -> 21069N087E | F10: ok | G10: =_xlfn.XLOOKUP(Tabla1[[#This Row],[SERIE]],'DATA IT'!D:D,'DATA IT'!G:G) -> RP4B | H10: NOK
A11: RP4-A00N0B02 | B11: DS00B2 | C11: JUAN CARLOS RAMIREZ SIBRIAN | D11: S/N 21069N0882 | E11: =RIGHT(Tabla1[[#This Row],[NUMERO DE SERIE ]],10) -> 21069N0882 | F11: ok | G11: =_xlfn.XLOOKUP(Tabla1[[#This Row],[SERIE]],'DATA IT'!D:D,'DATA IT'!G:G) -> RP4B
A12: RP4-A00N0B02 | B12: DS0081 | C12: BRYAN GALDÁMEZ | D12: S/N 21069N0896 | E12: =RIGHT(Tabla1[[#This Row],[NUMERO DE SERIE ]],10) -> 21069N0896 | F12: ok | G12: =_xlfn.XLOOKUP(Tabla1[[#This Row],[SERIE]],'DATA IT'!D:D,'DATA IT'!G:G) -> RP4B
A13: RP4-A00N0B02 | B13: Pendiente de Asignar | C13: Coordinación | D13: S/N 21069N089D | E13: =RIGHT(Tabla1[[#This Row],[NUMERO DE SERIE ]],10) -> 21069N089D | F13: ok | G13: =_xlfn.XLOOKUP(Tabla1[[#This Row],[SERIE]],'DATA IT'!D:D,'DATA IT'!G:G) -> RP4B | H13: NOK
A14: RP4-A00N0B02 | B14: Pendiente de Asignar | C14: Coordinación | D14: S/N 21069N08B7 | E14: =RIGHT(Tabla1[[#This Row],[NUMERO DE SERIE ]],10) -> 21069N08B7 | F14: ok | G14: =_xlfn.XLOOKUP(Tabla1[[#This Row],[SERIE]],'DATA IT'!D:D,'DATA IT'!G:G) -> RP4B | H14: NOK
A15: RP4-A00N0B02 | B15: Pendiente de Asignar | C15: Coordinación | D15: S/N 21070N020A | E15: =RIGHT(Tabla1[[#This Row],[NUMERO DE SERIE ]],10) -> 21070N020A | F15: ok | G15: =_xlfn.XLOOKUP(Tabla1[[#This Row],[SERIE]],'DATA IT'!D:D,'DATA IT'!G:G) -> RP4B | H15: NOK | I15: No funciona
A16: RP4-A00N0B02 | B16: DS0058 | C16: JOSE ALEXANDER GARCIA SAÑA | D16: S/N 21070N0211 | E16: =RIGHT(Tabla1[[#This Row],[NUMERO DE SERIE ]],10) -> 21070N0211 | F16: ok | G16: =_xlfn.XLOOKUP(Tabla1[[#This Row],[SERIE]],'DATA IT'!D:D,'DATA IT'!G:G) -> RP4B
A17: RP4-A00N0B02 | B17: DS00DD | C17: BRYAN GALDÁMEZ | D17: S/N 21070N0212 | E17: =RIGHT(Tabla1[[#This Row],[NUMERO DE SERIE ]],10) -> 21070N0212 | F17: ok | G17: =_xlfn.XLOOKUP(Tabla1[[#This Row],[SERIE]],'DATA IT'!D:D,'DATA IT'!G:G) -> RP4B
A18: RP4-A00N0B02 | B18: Pendiente de Asignar | C18: Coordinación | D18: S/N 21076N09A9 | E18: =RIGHT(Tabla1[[#This Row],[NUMERO DE SERIE ]],10) -> 21076N09A9 | F18: ok | G18: =_xlfn.XLOOKUP(Tabla1[[#This Row],[SERIE]],'DATA IT'!D:D,'DATA IT'!G:G) -> RP4B | H18: NOK
A19: RP4-A00N0B02 | B19: DS00H4 | C19: KASSANDRA HERNÁNDEZ | D19: S/N 21076N09B0 | E19: =RIGHT(Tabla1[[#This Row],[NUMERO DE SERIE ]],10) -> 21076N09B0 | F19: ok | G19: =_xlfn.XLOOKUP(Tabla1[[#This Row],[SERIE]],'DATA IT'!D:D,'DATA IT'!G:G) -> RP4B | H19: NOK
A20: RP4-A00N0B02 | B20: DS0075 | C20: ELMER FIGUEROA | D20: S/N 21076N09B1 | E20: =RIGHT(Tabla1[[#This Row],[NUMERO DE SERIE ]],10) -> 21076N09B1 | F20: ok | G20: =_xlfn.XLOOKUP(Tabla1[[#This Row],[SERIE]],'DATA IT'!D:D,'DATA IT'!G:G) -> RP4B
A21: RP4-A00N0B02 | B21: DS0061 | C21: ELMER FIGUEROA | D21: S/N 21076N09B5 | E21: =RIGHT(Tabla1[[#This Row],[NUMERO DE SERIE ]],10) -> 21076N09B5 | F21: ok | G21: =_xlfn.XLOOKUP(Tabla1[[#This Row],[SERIE]],'DATA IT'!D:D,'DATA IT'!G:G) -> RP4B
A22: RP4-A00N0B02 | B22: Pendiente de Asignar | C22: Coordinación | D22: S/N 21076N09B6 | E22: =RIGHT(Tabla1[[#This Row],[NUMERO DE SERIE ]],10) -> 21076N09B6 | F22: ok | G22: =_xlfn.XLOOKUP(Tabla1[[#This Row],[SERIE]],'DATA IT'!D:D,'DATA IT'!G:G) -> RP4B | H22: NOK
A23: RP4-A00N0B02 | B23: Pendiente de Asignar | C23: Coordinación | D23: S/N21076N09C3 | E23: =RIGHT(Tabla1[[#This Row],[NUMERO DE SERIE ]],10) -> 21076N09C3 | F23: ok | G23: =_xlfn.XLOOKUP(Tabla1[[#This Row],[SERIE]],'DATA IT'!D:D,'DATA IT'!G:G) -> RP4B | H23: NOK
A24: RP4-A00N0B02 | B24: DS0004 | C24: JUAN CARLOS RAMIREZ SIBRIAN | D24: S/N 21076N09C4 | E24: =RIGHT(Tabla1[[#This Row],[NUMERO DE SERIE ]],10) -> 21076N09C4 | F24: ok | G24: =_xlfn.XLOOKUP(Tabla1[[#This Row],[SERIE]],'DATA IT'!D:D,'DATA IT'!G:G) -> RP4B | I24: NO FUNCIONA
A25: N/D | B25: Pendiente de Asignar | C25: Coordinación | D25: N/D | E25: =RIGHT(Tabla1[[#This Row],[NUMERO DE SERIE ]],10) -> N/D | G25: =_xlfn.XLOOKUP(Tabla1[[#This Row],[SERIE]],'DATA IT'!D:D,'DATA IT'!G:G) -> #N/A | H25: NOK
A26: N/D | B26: Pendiente de Asignar | C26: Coordinación | D26: N/D | E26: =RIGHT(Tabla1[[#This Row],[NUMERO DE SERIE ]],10) -> N/D | G26: =_xlfn.XLOOKUP(Tabla1[[#This Row],[SERIE]],'DATA IT'!D:D,'DATA IT'!G:G) -> #N/A | H26: NOK
A27: RP4-A00N0B02 | B27: DS00T6 | C27: ELMER FIGUEROA | D27: S/N 21076N09C8 | E27: =RIGHT(Tabla1[[#This Row],[NUMERO DE SERIE ]],10) -> 21076N09C8 | F27: ok | G27: =_xlfn.XLOOKUP(Tabla1[[#This Row],[SERIE]],'DATA IT'!D:D,'DATA IT'!G:G) -> RP4B
A28: RP4-A00N0B02 | B28: DS0041 | C28: JUAN CARLOS RAMIREZ SIBRIAN | D28: S/N 21076N0B1C | E28: =RIGHT(Tabla1[[#This Row],[NUMERO DE SERIE ]],10) -> 21076N0B1C | F28: ok | G28: =_xlfn.XLOOKUP(Tabla1[[#This Row],[SERIE]],'DATA IT'!D:D,'DATA IT'!G:G) -> RP4B
A29: RP4-A00N0B02 | B29: DS0045 | C29: JUAN CARLOS RAMIREZ SIBRIAN | D29: S/N 21076N0B1E | E29: =RIGHT(Tabla1[[#This Row],[NUMERO DE SERIE ]],10) -> 21076N0B1E | F29: ok | G29: =_xlfn.XLOOKUP(Tabla1[[#This Row],[SERIE]],'DATA IT'!D:D,'DATA IT'!G:G) -> RP4B
A30: RP4-A00N0B02 | B30: DS0025 | C30: BRYAN GALDÁMEZ | D30: S/N 21076N0B1F | E30: =RIGHT(Tabla1[[#This Row],[NUMERO DE SERIE ]],10) -> 21076N0B1F | F30: ok | G30: =_xlfn.XLOOKUP(Tabla1[[#This Row],[SERIE]],'DATA IT'!D:D,'DATA IT'!G:G) -> RP4B
A31: RP4-A00N0B02 | B31: DS0039 | C31: JUAN CARLOS RAMIREZ SIBRIAN | D31: S/N 21076N0B20 | E31: =RIGHT(Tabla1[[#This Row],[NUMERO DE SERIE ]],10) -> 21076N0B20 | F31: ok | G31: =_xlfn.XLOOKUP(Tabla1[[#This Row],[SERIE]],'DATA IT'!D:D,'DATA IT'!G:G) -> RP4B
A32: RP4-A00N0B02 | B32: DS00D4 | C32: JOSE ALEXANDER GARCIA SAÑA | D32: S/N 21076N0B32 | E32: =RIGHT(Tabla1[[#This Row],[NUMERO DE SERIE ]],10) -> 21076N0B32 | F32: ok | G32: =_xlfn.XLOOKUP(Tabla1[[#This Row],[SERIE]],'DATA IT'!D:D,'DATA IT'!G:G) -> RP4B
A33: RP4-A00N0B02 | B33: DS0021 | C33: BRYAN GALDÁMEZ | D33: S/N 21076N0B34 | E33: =RIGHT(Tabla1[[#This Row],[NUMERO DE SERIE ]],10) -> 21076N0B34 | F33: ok | G33: =_xlfn.XLOOKUP(Tabla1[[#This Row],[SERIE]],'DATA IT'!D:D,'DATA IT'!G:G) -> RP4B
A34: RP4-A00N0B02 | B34: DS0074 | C34: JUAN CARLOS RAMIREZ SIBRIAN | D34: S/N 21076N0B36 | E34: =RIGHT(Tabla1[[#This Row],[NUMERO DE SERIE ]],10) -> 21076N0B36 | F34: ok | G34: =_xlfn.XLOOKUP(Tabla1[[#This Row],[SERIE]],'DATA IT'!D:D,'DATA IT'!G:G) -> RP4B
A35: RP4-A00N0B02 | B35: DS0089 | C35: BRYAN GALDÁMEZ | D35: S/N 21076N0B39 | E35: =RIGHT(Tabla1[[#This Row],[NUMERO DE SERIE ]],10) -> 21076N0B39 | F35: ok | G35: =_xlfn.XLOOKUP(Tabla1[[#This Row],[SERIE]],'DATA IT'!D:D,'DATA IT'!G:G) -> RP4B
A36: RP4-A00N0B02 | B36: DS0090 | C36: BRYAN GALDÁMEZ | D36: S/N 21076N0B3A | E36: =RIGHT(Tabla1[[#This Row],[NUMERO DE SERIE ]],10) -> 21076N0B3A | F36: ok | G36: =_xlfn.XLOOKUP(Tabla1[[#This Row],[SERIE]],'DATA IT'!D:D,'DATA IT'!G:G) -> RP4B
A37: RP4-A00N0B02 | B37: DS0064 | C37: JUAN CARLOS RAMIREZ SIBRIAN | D37: S/N 21076N0B3C | E37: =RIGHT(Tabla1[[#This Row],[NUMERO DE SERIE ]],10) -> 21076N0B3C | F37: ok | G37: =_xlfn.XLOOKUP(Tabla1[[#This Row],[SERIE]],'DATA IT'!D:D,'DATA IT'!G:G) -> RP4B
A38: RP4-A00N0B02 | B38: DS0088 | C38: ELMER FIGUEROA | D38: S/N 21076N0B44 | E38: =RIGHT(Tabla1[[#This Row],[NUMERO DE SERIE ]],10) -> 21076N0B44 | F38: ok | G38: =_xlfn.XLOOKUP(Tabla1[[#This Row],[SERIE]],'DATA IT'!D:D,'DATA IT'!G:G) -> RP4B
A39: N/D | B39: Pendiente de Asignar | C39: Coordinación | D39: N/D | E39: =RIGHT(Tabla1[[#This Row],[NUMERO DE SERIE ]],10) -> N/D | G39: =_xlfn.XLOOKUP(Tabla1[[#This Row],[SERIE]],'DATA IT'!D:D,'DATA IT'!G:G) -> #N/A | H39: NOK
A40: RP4-A00N0B02 | B40: DS0029 | C40: JOSE ALEXANDER GARCIA SAÑA | D40: S/N 21076N0B45 | E40: =RIGHT(Tabla1[[#This Row],[NUMERO DE SERIE ]],10) -> 21076N0B45 | F40: ok | G40: =_xlfn.XLOOKUP(Tabla1[[#This Row],[SERIE]],'DATA IT'!D:D,'DATA IT'!G:G) -> RP4B | H40: NOK
...

Sheet DATA IT
A1: N° | B1: Estado | C1: Nombre | D1: Número de serie | F1: Fabricante | G1: Modelo | H1: Ubicación | I1: Asignado a | J1: Comentarios | K1: Buscar
A2: 283 | B2: Activo | C2: MAZPRNES-21069N006F | D2: 21069N006F | F2: Honeywell | G2: RP4B | H2: SV_ESR_CD_Soyapango | I2: Felix Chavez | K2: =_xlfn.XLOOKUP(D2,'Impresoras Julio 2026'!E:E,'Impresoras Julio 2026'!F:F) -> #N/A
A3: 284 | B3: Activo | C3: MAZPRNES-21069N007D | D3: 21069N007D | E3: 21069N007D | F3: Honeywell | G3: RP4B | H3: SV_ESR_CD_Soyapango | I3: Felix Chavez | K3: =_xlfn.XLOOKUP(D3,'Impresoras Julio 2026'!E:E,'Impresoras Julio 2026'!F:F) -> ok
A4: 285 | B4: Activo | C4: MAZPRNES-21069N007E | D4: 21069N007E | E4: 21069N007E | F4: Honeywell | G4: RP4B | H4: SV_ESR_CD_Soyapango | I4: Felix Chavez | K4: =_xlfn.XLOOKUP(D4,'Impresoras Julio 2026'!E:E,'Impresoras Julio 2026'!F:F) -> ok
A5: 286 | B5: Activo | C5: MAZPRNES-21069N007F | D5: 21069N007F | E5: 21069N007F | F5: Honeywell | G5: RP4B | H5: SV_ESR_CD_Soyapango | I5: Felix Chavez | K5: =_xlfn.XLOOKUP(D5,'Impresoras Julio 2026'!E:E,'Impresoras Julio 2026'!F:F) -> ok
A6: 287 | B6: Activo | C6: MAZPRNES-21069N0097 | D6: 21069N0097 | E6: 21069N0097 | F6: Honeywell | G6: RP4B | H6: SV_ESR_CD_Soyapango | I6: Felix Chavez | K6: =_xlfn.XLOOKUP(D6,'Impresoras Julio 2026'!E:E,'Impresoras Julio 2026'!F:F) -> ok
A7: 288 | B7: Activo | C7: MAZPRNES-21069N0098 | D7: 21069N0098 | E7: 21069N0098 | F7: Honeywell | G7: RP4B | H7: SV_ESR_CD_Soyapango | I7: Felix Chavez | K7: =_xlfn.XLOOKUP(D7,'Impresoras Julio 2026'!E:E,'Impresoras Julio 2026'!F:F) -> ok
A8: 289 | B8: Activo | C8: MAZPRNES-21069N0099 | D8: 21069N0099 | E8: 21069N0099 | F8: Honeywell | G8: RP4B | H8: SV_ESR_CD_Soyapango | I8: Felix Chavez | K8: =_xlfn.XLOOKUP(D8,'Impresoras Julio 2026'!E:E,'Impresoras Julio 2026'!F:F) -> ok
A9: 290 | B9: Activo | C9: MAZPRNES-21069N009A | D9: 21069N009A | E9: 21069N009A | F9: Honeywell | G9: RP4B | H9: SV_ESR_CD_Soyapango | I9: Felix Chavez | K9: =_xlfn.XLOOKUP(D9,'Impresoras Julio 2026'!E:E,'Impresoras Julio 2026'!F:F) -> ok
A10: 291 | B10: Activo | C10: MAZPRNES-21069N0874 | D10: 21069N0874 | E10: 21069N0874 | F10: Honeywell | G10: RP4B | H10: SV_ESR_CD_Soyapango | I10: Felix Chavez | K10: =_xlfn.XLOOKUP(D10,'Impresoras Julio 2026'!E:E,'Impresoras Julio 2026'!F:F) -> ok
A11: 292 | B11: Activo | C11: MAZPRNES-21069N087E | D11: 21069N087E | E11: 21069N087E | F11: Honeywell | G11: RP4B | H11: SV_ESR_CD_Soyapango | I11: Felix Chavez | K11: =_xlfn.XLOOKUP(D11,'Impresoras Julio 2026'!E:E,'Impresoras Julio 2026'!F:F) -> ok
A12: 293 | B12: Activo | C12: MAZPRNES-21069N0882 | D12: 21069N0882 | E12: 21069N0882 | F12: Honeywell | G12: RP4B | H12: SV_ESR_CD_Soyapango | I12: Felix Chavez | K12: =_xlfn.XLOOKUP(D12,'Impresoras Julio 2026'!E:E,'Impresoras Julio 2026'!F:F) -> ok
A13: 294 | B13: Activo | C13: MAZPRNES-21069N0896 | D13: 21069N0896 | E13: 21069N0896 | F13: Honeywell | G13: RP4B | H13: SV_ESR_CD_Soyapango | I13: Felix Chavez | K13: =_xlfn.XLOOKUP(D13,'Impresoras Julio 2026'!E:E,'Impresoras Julio 2026'!F:F) -> ok
A14: 295 | B14: Activo | C14: MAZPRNES-21069N089C | D14: 21069N089C | F14: Honeywell | G14: RP4B | H14: SV_ESR_CD_Soyapango | I14: Felix Chavez | K14: =_xlfn.XLOOKUP(D14,'Impresoras Julio 2026'!E:E,'Impresoras Julio 2026'!F:F) -> #N/A
A15: 296 | B15: Activo | C15: MAZPRNES-21069N089D | D15: 21069N089D | E15: 21069N089D | F15: Honeywell | G15: RP4B | H15: SV_ESR_CD_Soyapango | I15: Felix Chavez | K15: =_xlfn.XLOOKUP(D15,'Impresoras Julio 2026'!E:E,'Impresoras Julio 2026'!F:F) -> ok
A16: 297 | B16: Activo | C16: MAZPRNES-21069N08B7 | D16: 21069N08B7 | E16: 21069N08B7 | F16: Honeywell | G16: RP4B | H16: SV_ESR_CD_Soyapango | I16: Felix Chavez | K16: =_xlfn.XLOOKUP(D16,'Impresoras Julio 2026'!E:E,'Impresoras Julio 2026'!F:F) -> ok
A17: 298 | B17: Activo | C17: MAZPRNES-21070N020A | D17: 21070N020A | E17: 21070N020A | F17: Honeywell | G17: RP4B | H17: SV_ESR_CD_Soyapango | I17: Felix Chavez | K17: =_xlfn.XLOOKUP(D17,'Impresoras Julio 2026'!E:E,'Impresoras Julio 2026'!F:F) -> ok
A18: 299 | B18: Activo | C18: MAZPRNES-21070N0211 | D18: 21070N0211 | E18: 21070N0211 | F18: Honeywell | G18: RP4B | H18: SV_ESR_CD_Soyapango | I18: Felix Chavez | K18: =_xlfn.XLOOKUP(D18,'Impresoras Julio 2026'!E:E,'Impresoras Julio 2026'!F:F) -> ok
A19: 300 | B19: Activo | C19: MAZPRNES-21070N0212 | D19: 21070N0212 | E19: 21070N0212 | F19: Honeywell | G19: RP4B | H19: SV_ESR_CD_Soyapango | I19: Felix Chavez | K19: =_xlfn.XLOOKUP(D19,'Impresoras Julio 2026'!E:E,'Impresoras Julio 2026'!F:F) -> ok
A20: 301 | B20: Activo | C20: MAZPRNES-21076N09A6 | D20: 21076N09A6 | F20: Honeywell | G20: RP4B | H20: SV_ESR_CD_Soyapango | I20: Felix Chavez | K20: =_xlfn.XLOOKUP(D20,'Impresoras Julio 2026'!E:E,'Impresoras Julio 2026'!F:F) -> #N/A
A21: 302 | B21: Activo | C21: MAZPRNES-21076N09A9 | D21: 21076N09A9 | E21: 21076N09A9 | F21: Honeywell | G21: RP4B | H21: SV_ESR_CD_Soyapango | I21: Felix Chavez | K21: =_xlfn.XLOOKUP(D21,'Impresoras Julio 2026'!E:E,'Impresoras Julio 2026'!F:F) -> ok
A22: 303 | B22: Activo | C22: MAZPRNES-21076N09AA | D22: 21076N09AA | F22: Honeywell | G22: RP4B | H22: SV_ESR_CD_Soyapango | I22: Felix Chavez | K22: =_xlfn.XLOOKUP(D22,'Impresoras Julio 2026'!E:E,'Impresoras Julio 2026'!F:F) -> #N/A
A23: 304 | B23: Activo | C23: MAZPRNES-21076N09AE | D23: 21076N09AE | F23: Honeywell | G23: RP4B | H23: SV_ESR_CD_Soyapango | I23: Felix Chavez | K23: =_xlfn.XLOOKUP(D23,'Impresoras Julio 2026'!E:E,'Impresoras Julio 2026'!F:F) -> #N/A
A24: 305 | B24: Activo | C24: MAZPRNES-21076N09B0 | D24: 21076N09B0 | E24: 21076N09B0 | F24: Honeywell | G24: RP4B | H24: SV_ESR_CD_Soyapango | I24: Felix Chavez | K24: =_xlfn.XLOOKUP(D24,'Impresoras Julio 2026'!E:E,'Impresoras Julio 2026'!F:F) -> ok
A25: 306 | B25: Activo | C25: MAZPRNES-21076N09B1 | D25: 21076N09B1 | E25: 21076N09B1 | F25: Honeywell | G25: RP4B | H25: SV_ESR_CD_Soyapango | I25: Felix Chavez | K25: =_xlfn.XLOOKUP(D25,'Impresoras Julio 2026'!E:E,'Impresoras Julio 2026'!F:F) -> ok
A26: 307 | B26: Activo | C26: MAZPRNES-21076N09B5 | D26: 21076N09B5 | E26: 21076N09B5 | F26: Honeywell | G26: RP4B | H26: SV_ESR_CD_Soyapango | I26: Felix Chavez | K26: =_xlfn.XLOOKUP(D26,'Impresoras Julio 2026'!E:E,'Impresoras Julio 2026'!F:F) -> ok
A27: 308 | B27: Activo | C27: MAZPRNES-21076N09B6 | D27: 21076N09B6 | E27: 21076N09B6 | F27: Honeywell | G27: RP4B | H27: SV_ESR_CD_Soyapango | I27: Felix Chavez | K27: =_xlfn.XLOOKUP(D27,'Impresoras Julio 2026'!E:E,'Impresoras Julio 2026'!F:F) -> ok
A28: 309 | B28: Activo | C28: MAZPRNES-21076N09B8 | D28: 21076N09B8 | F28: Honeywell | G28: RP4B | H28: SV_ESR_CD_Soyapango | I28: Felix Chavez | K28: =_xlfn.XLOOKUP(D28,'Impresoras Julio 2026'!E:E,'Impresoras Julio 2026'!F:F) -> #N/A
A29: 310 | B29: Activo | C29: MAZPRNES-21076N09BE | D29: 21076N09BE | F29: Honeywell | G29: RP4B | H29: SV_ESR_CD_Soyapango | I29: Felix Chavez | K29: =_xlfn.XLOOKUP(D29,'Impresoras Julio 2026'!E:E,'Impresoras Julio 2026'!F:F) -> #N/A
A30: 311 | B30: Activo | C30: MAZPRNES-21076N09C2 | D30: 21076N09C2 | F30: Honeywell | G30: RP4B | H30: SV_ESR_CD_Soyapango | I30: Felix Chavez | K30: =_xlfn.XLOOKUP(D30,'Impresoras Julio 2026'!E:E,'Impresoras Julio 2026'!F:F) -> #N/A
A31: 312 | B31: Activo | C31: MAZPRNES-21076n09c3 | D31: 21076n09c3 | E31: 21076N09C3 | F31: Honeywell | G31: RP4B | H31: SV_ESR_CD_Soyapango | I31: Felix Chavez | K31: =_xlfn.XLOOKUP(D31,'Impresoras Julio 2026'!E:E,'Impresoras Julio 2026'!F:F) -> ok
A32: 313 | B32: Activo | C32: MAZPRNES-21076N09C4 | D32: 21076N09C4 | E32: 21076N09C4 | F32: Honeywell | G32: RP4B | H32: SV_ESR_CD_Soyapango | I32: Felix Chavez | K32: =_xlfn.XLOOKUP(D32,'Impresoras Julio 2026'!E:E,'Impresoras Julio 2026'!F:F) -> ok
A33: 314 | B33: Activo | C33: MAZPRNES-21076N09C6 | D33: 21076N09C6 | F33: Honeywell | G33: RP4B | H33: SV_ESR_CD_Soyapango | I33: Felix Chavez | K33: =_xlfn.XLOOKUP(D33,'Impresoras Julio 2026'!E:E,'Impresoras Julio 2026'!F:F) -> #N/A
A34: 315 | B34: Activo | C34: MAZPRNES-21076N09C8 | D34: 21076N09C8 | E34: 21076N09C8 | F34: Honeywell | G34: RP4B | H34: SV_ESR_CD_Soyapango | I34: Felix Chavez | K34: =_xlfn.XLOOKUP(D34,'Impresoras Julio 2026'!E:E,'Impresoras Julio 2026'!F:F) -> ok
A35: 316 | B35: Activo | C35: MAZPRNES-21076N0B1C | D35: 21076N0B1C | E35: 21076N0B1C | F35: Honeywell | G35: RP4B | H35: SV_ESR_CD_Soyapango | I35: Felix Chavez | K35: =_xlfn.XLOOKUP(D35,'Impresoras Julio 2026'!E:E,'Impresoras Julio 2026'!F:F) -> ok
A36: 317 | B36: Activo | C36: MAZPRNES-21076n0b1e | D36: 21076n0b1e | E36: 21076N0B1E | F36: Honeywell | G36: RP4B | H36: SV_ESR_CD_Soyapango | I36: Felix Chavez | K36: =_xlfn.XLOOKUP(D36,'Impresoras Julio 2026'!E:E,'Impresoras Julio 2026'!F:F) -> ok
A37: 318 | B37: Activo | C37: MAZPRNES-21076N0B1F | D37: 21076N0B1F | E37: 21076N0B1F | F37: Honeywell | G37: RP4B | H37: SV_ESR_CD_Soyapango | I37: Felix Chavez | K37: =_xlfn.XLOOKUP(D37,'Impresoras Julio 2026'!E:E,'Impresoras Julio 2026'!F:F) -> ok
A38: 319 | B38: Activo | C38: MAZPRNES-21076n0b20 | D38: 21076n0b20 | E38: 21076N0B20 | F38: Honeywell | G38: RP4B | H38: SV_ESR_CD_Soyapango | I38: Felix Chavez | K38: =_xlfn.XLOOKUP(D38,'Impresoras Julio 2026'!E:E,'Impresoras Julio 2026'!F:F) -> ok
A39: 320 | B39: Activo | C39: MAZPRNES-21076N0B23 | D39: 21076N0B23 | F39: Honeywell | G39: RP4B | H39: SV_ESR_CD_Soyapango | I39: Felix Chavez | K39: =_xlfn.XLOOKUP(D39,'Impresoras Julio 2026'!E:E,'Impresoras Julio 2026'!F:F) -> #N/A
A40: 321 | B40: Activo | C40: MAZPRNES-21076N0B30 | D40: 21076N0B30 | F40: Honeywell | G40: RP4B | H40: SV_ESR_CD_Soyapango | I40: Felix Chavez | K40: =_xlfn.XLOOKUP(D40,'Impresoras Julio 2026'!E:E,'Impresoras Julio 2026'!F:F) -> #N/A
...
